#VRML_SIM R2025a utf8

EXTERNPROTO "https://raw.githubusercontent.com/cyberbotics/webots/R2023b/projects/objects/backgrounds/protos/TexturedBackground.proto"
EXTERNPROTO "https://raw.githubusercontent.com/cyberbotics/webots/R2023b/projects/objects/backgrounds/protos/TexturedBackgroundLight.proto"
EXTERNPROTO "https://raw.githubusercontent.com/cyberbotics/webots/R2023b/projects/objects/floors/protos/RectangleArena.proto"
EXTERNPROTO "https://raw.githubusercontent.com/cyberbotics/webots/R2023b/projects/objects/factory/containers/protos/WoodenBox.proto"

WorldInfo {
  info [
    "Simple e-puck simulation that can be controlled with ROS2."
  ]
  title "ROS2 simulation of the e-puck robot"
  basicTimeStep 20
}
Viewpoint {
  orientation 0.28362777855073124 -0.5584526932963291 -0.7795420916053561 5.123027735160639
  position -2.0143180997362857 -2.9063125700840695 2.8002042398093248
}
TexturedBackground {
}
TexturedBackgroundLight {
}
RectangleArena {
  floorSize 1.5 1.5
}
WoodenBox {
  translation -0.265062 0.13 0.05
  name "wooden box(1)"
  size 0.1 0.1 0.1
}
WoodenBox {
  translation -0.115895 -0.36 0.05
  name "wooden box(2)"
  size 0.1 0.1 0.1
}
WoodenBox {
  translation 0.44 0.12 0.05
  name "wooden box(3)"
  size 0.1 0.1 0.1
}
WoodenBox {
  translation 0.29726 -0.29 0.05
  name "wooden box(4)"
  size 0.1 0.1 0.1
}
WoodenBox {
  translation -0.158467 0.26 0.05
  size 0.1 0.1 0.1
}
DEF MY_ROBOT Robot {
  translation 0 0 0.001
  children [
    Lidar {
      translation 0 0 0.05
      name "lidar2D"
      horizontalResolution 360
      fieldOfView 6.28
      numberOfLayers 1
    }
    HingeJoint {
      jointParameters HingeJointParameters {
        position 1.7860363493046087e-07
        axis 0 1 0
        anchor 0 0 0.025
      }
      device [
        RotationalMotor {
          name "left wheel motor"
        }
        PositionSensor {
          name "left wheel encoder"
        }
      ]
      endPoint Solid {
        translation 0 0.045 0.025
        rotation 0 1 0 0
        children [
          DEF WHEEL Pose {
            rotation 1 0 0 1.5707996938995747
            children [
              Shape {
                appearance PBRAppearance {
                  baseColor 1 0 0
                  roughness 1
                  metalness 0
                }
                geometry Cylinder {
                  height 0.0001
                  radius 0.025
                }
              }
            ]
          }
        ]
        name "left wheel"
        boundingObject USE WHEEL
        physics Physics {
        }
      }
    }
    HingeJoint {
      jointParameters HingeJointParameters {
        axis 0 1 0
        anchor 0 0 0.025
      }
      device [
        RotationalMotor {
          name "right wheel motor"
        }
        PositionSensor {
          name "right wheel encoder"
        }
      ]
      endPoint Solid {
        translation 0 -0.045 0.025
        rotation 0 1 0 0
        children [
          USE WHEEL
        ]
        name "right wheel"
        boundingObject USE WHEEL
        physics Physics {
        }
      }
    }
    Pose {
      translation 0 0 0.0415
      children [
        Shape {
          appearance PBRAppearance {
            baseColor 0 0 1
            roughness 1
            metalness 0
          }
          geometry DEF BODY Cylinder {
            height 0.08
            radius 0.045
          }
        }
      ]
    }
  ]
  name "my_robot"
  boundingObject Pose {
    translation 0 0 0.0415
    children [
      USE BODY
    ]
  }
  physics Physics {
  }
  controller "<extern>"
  supervisor TRUE
}
